<?xml version="1.0"?>
<robot name="Robot_Dog">


  <!--########## MIDSECTION OBJECTS ##########-->

  <!--##### midsection-bottom (base link) #####-->

  <link name="midsection_bottom">
    <visual>
      <geometry>
        <mesh filename="/home/matthewthomasbeck/Projects/Robot_Dog/training/meshes/midsection/ares_midsection_bottom.dae" scale="1 1 1"/>
      </geometry>

      <material name="Grey">
        <color rgba="0.5 0.5 0.5 1"/>
      </material>
    </visual>

    <collision>
      <geometry>
        <mesh filename="/home/matthewthomasbeck/Projects/Robot_Dog/training/meshes/midsection/ares_midsection_bottom.dae" scale="1 1 1"/>
      </geometry>
    </collision>

    <inertial>
      <mass value="0.089"/> <!-- Adjust mass if necessary -->
      <inertia ixx="0.001" ixy="0.0" ixz="0.0" iyy="0.001" iyz="0.0" izz="0.001"/>
      <origin xyz="0 0 0" rpy="0 0 0"/>
    </inertial>
  </link>

  <!--##### midsection-top #####-->

  <link name="midsection_top">
    <visual>
      <origin xyz="0 0 0" rpy="0 0 0"/>
      <geometry>
        <mesh filename="/home/matthewthomasbeck/Projects/Robot_Dog/training/meshes/midsection/athena_midsection_top.dae" scale="1 1 1"/>
      </geometry>

      <material name="Grey">
        <color rgba="0.5 0.5 0.5 1"/>
      </material>
    </visual>

    <collision>
      <origin xyz="0 0 0" rpy="0 0 0"/>
      <geometry>
        <mesh filename="/home/matthewthomasbeck/Projects/Robot_Dog/training/meshes/midsection/athena_midsection_top.dae" scale="1 1 1"/>
      </geometry>
    </collision>

    <inertial>
      <mass value="0.042"/>
      <inertia ixx="0.001" ixy="0.0" ixz="0.0" iyy="0.001" iyz="0.0" izz="0.001"/>
      <origin xyz="0 0 0" rpy="0 0 0"/>
    </inertial>
  </link>

  <!--##### midsection-connectorplate #####-->

  <link name="midsection_connectorplate">
    <visual>
      <origin xyz="0 0 0" rpy="0 0 0"/>
      <geometry>
        <mesh filename="/home/matthewthomasbeck/Projects/Robot_Dog/training/meshes/midsection/athena_midsection_connectorplate.dae" scale="1 1 1"/>
      </geometry>

      <material name="Grey">
        <color rgba="0.5 0.5 0.5 1"/>
      </material>
    </visual>

    <collision>
      <origin xyz="0 0 0" rpy="0 0 0"/>
      <geometry>
        <mesh filename="/home/matthewthomasbeck/Projects/Robot_Dog/training/meshes/midsection/athena_midsection_connectorplate.dae" scale="1 1 1"/>
      </geometry>
    </collision>

    <inertial>
      <mass value="0.020"/>
      <inertia ixx="0.001" ixy="0.0" ixz="0.0" iyy="0.001" iyz="0.0" izz="0.001"/>
      <origin xyz="0 0 0" rpy="0 0 0"/>
    </inertial>
  </link>

  <!--##### midsection-batteryplate #####-->

  <link name="midsection_batteryplate">
    <visual>
      <origin xyz="0 0 0" rpy="0 0 0"/>
      <geometry>
        <mesh filename="/home/matthewthomasbeck/Projects/Robot_Dog/training/meshes/midsection/ares_midsection_batteryplate.dae" scale="1 1 1"/>
      </geometry>

      <material name="Grey">
        <color rgba="0.5 0.5 0.5 1"/>
      </material>
    </visual>

    <collision>
      <origin xyz="0 0 0" rpy="0 0 0"/>
      <geometry>
        <mesh filename="/home/matthewthomasbeck/Projects/Robot_Dog/training/meshes/midsection/ares_midsection_batteryplate.dae" scale="1 1 1"/>
      </geometry>
    </collision>

    <inertial>
      <mass value="0.022"/>
      <inertia ixx="0.001" ixy="0.0" ixz="0.0" iyy="0.001" iyz="0.0" izz="0.001"/>
      <origin xyz="0 0 0" rpy="0 0 0"/>
    </inertial>
  </link>

  <!--##### midsection-side-left #####-->

  <link name="midsection_side_left">
    <visual>
      <origin xyz="0 0 0" rpy="0 0 0"/>
      <geometry>
        <mesh filename="/home/matthewthomasbeck/Projects/Robot_Dog/training/meshes/midsection/ares_midsection_side.dae" scale="1 1 1"/>
      </geometry>

      <material name="Grey">
        <color rgba="0.5 0.5 0.5 1"/>
      </material>
    </visual>

    <collision>
      <origin xyz="0 0 0" rpy="0 0 0"/>
      <geometry>
        <mesh filename="/home/matthewthomasbeck/Projects/Robot_Dog/training/meshes/midsection/ares_midsection_side.dae" scale="1 1 1"/>
      </geometry>
    </collision>

    <inertial>
      <mass value="0.023"/>
      <inertia ixx="0.001" ixy="0.0" ixz="0.0" iyy="0.001" iyz="0.0" izz="0.001"/>
      <origin xyz="0 0 0" rpy="0 0 0"/>
    </inertial>
  </link>

  <!--##### midsection-side-right #####-->

  <link name="midsection_side_right">
    <visual>
      <origin xyz="0 0 0" rpy="0 0 0"/>
      <geometry>
        <mesh filename="/home/matthewthomasbeck/Projects/Robot_Dog/training/meshes/midsection/ares_midsection_side.dae" scale="1 1 1"/>
      </geometry>

      <material name="Grey">
        <color rgba="0.5 0.5 0.5 1"/>
      </material>
    </visual>

    <collision>
      <origin xyz="0 0 0" rpy="0 0 0"/>
      <geometry>
        <mesh filename="/home/matthewthomasbeck/Projects/Robot_Dog/training/meshes/midsection/ares_midsection_side.dae" scale="1 1 1"/>
      </geometry>
    </collision>

    <inertial>
      <mass value="0.023"/>
      <inertia ixx="0.001" ixy="0.0" ixz="0.0" iyy="0.001" iyz="0.0" izz="0.001"/>
      <origin xyz="0 0 0" rpy="0 0 0"/>
    </inertial>
  </link>


  <!--########## MIDSECTION JOINTS ##########-->

  <!--##### midsection-bottom/top joint #####-->

  <joint name="midsection_bottom_top" type="fixed">
    <parent link="midsection_bottom"/>
    <child link="midsection_top"/>
    <origin xyz="0 0 0" rpy="0 0 0"/>
  </joint>

  <!--##### midsection-bottom/connectorplate joint #####-->

  <joint name="midsection_bottom_connectorplate" type="fixed">
    <parent link="midsection_bottom"/>
    <child link="midsection_connectorplate"/>
    <origin xyz="0.002 0.2 0.008" rpy="0 0 0"/>
  </joint>

  <!--##### midsection-top/batteryplate joint #####-->

  <joint name="midsection_top_batteryplate" type="fixed">
    <parent link="midsection_top"/>
    <child link="midsection_batteryplate"/>
    <origin xyz="-0.056 0.057 0.09855" rpy="0 0 0"/>
  </joint>

  <!--##### midsection-bottom/side-left joint #####-->

  <joint name="midsection_bottom_side_left" type="fixed">
    <parent link="midsection_bottom"/>
    <child link="midsection_side_left"/>
    <origin xyz="0 0 0" rpy="0 0 0"/>
  </joint>

  <!--##### midsection-bottom/side-right joint #####-->

  <joint name="midsection_bottom_side_right" type="fixed">
    <parent link="midsection_bottom"/>
    <child link="midsection_side_right"/>
    <origin xyz="-0.09705 0.1283 0" rpy="0 0 3.14"/>
  </joint>


  <!--########## FRONT OBJECTS ##########-->

  <!--##### front-face #####-->

  <link name="front_face">
    <visual>
      <origin xyz="0 0 0" rpy="0 0 0"/>
      <geometry>
          <mesh filename="/home/matthewthomasbeck/Projects/Robot_Dog/training/meshes/front/athena_front_face.dae" scale="1 1 1"/>
      </geometry>

      <material name="Grey">
          <color rgba="0.5 0.5 0.5 1"/>
      </material>
    </visual>

    <collision>
      <origin xyz="0 0 0" rpy="0 0 0"/>
      <geometry>
          <mesh filename="/home/matthewthomasbeck/Projects/Robot_Dog/training/meshes/front/athena_front_face.dae" scale="1 1 1"/>
      </geometry>
    </collision>

    <inertial>
      <mass value="0.035"/>
      <inertia ixx="0.001" ixy="0.0" ixz="0.0" iyy="0.001" iyz="0.0" izz="0.001"/>
      <origin xyz="0 0 0" rpy="0 0 0"/>
    </inertial>
  </link>

  <!--##### front-top #####-->

  <link name="front_top">
    <visual>
      <origin xyz="0 0 0" rpy="0 0 0"/>
      <geometry>
        <mesh filename="/home/matthewthomasbeck/Projects/Robot_Dog/training/meshes/front/athena_front_top.dae" scale="1 1 1"/>
      </geometry>

      <material name="Grey">
        <color rgba="0.5 0.5 0.5 1"/>
      </material>
    </visual>

    <collision>
      <origin xyz="0 0 0" rpy="0 0 0"/>
      <geometry>
          <mesh filename="/home/matthewthomasbeck/Projects/Robot_Dog/training/meshes/front/athena_front_top.dae" scale="1 1 1"/>
      </geometry>
    </collision>

    <inertial>
      <mass value="0.017"/>
      <inertia ixx="0.001" ixy="0.0" ixz="0.0" iyy="0.001" iyz="0.0" izz="0.001"/>
      <origin xyz="0 0 0" rpy="0 0 0"/>
    </inertial>
  </link>


  <!--########## FRONT JOINTS ##########-->

  <!--##### midsection-bottom/front-bottom joint #####-->

  <joint name="midsection_bottom_front_face" type="fixed">
    <parent link="midsection_bottom"/>
    <child link="front_face"/>
    <origin xyz="0.514 -0.043 -0.0794" rpy="0 0 3.14"/>
  </joint>

  <!--##### front-face/top joint #####-->

  <joint name="front_face_top" type="fixed">
    <parent link="front_face"/>
    <child link="front_top"/>
    <origin xyz="0.514 -0.042 0.07945" rpy="0 0 3.14"/>
  </joint>


  <!--########## BACK OBJECTS ##########-->

  <!--##### back-butt #####-->

  <link name="back_butt">
    <visual>
      <origin xyz="0 0 0" rpy="0 0 0"/>
      <geometry>
        <mesh filename="/home/matthewthomasbeck/Projects/Robot_Dog/training/meshes/back/athena_back_butt.dae" scale="1 1 1"/>
      </geometry>

      <material name="Grey">
          <color rgba="0.5 0.5 0.5 1"/>
      </material>
    </visual>

    <collision>
      <origin xyz="0 0 0" rpy="0 0 0"/>
      <geometry>
        <mesh filename="/home/matthewthomasbeck/Projects/Robot_Dog/training/meshes/back/athena_back_butt.dae" scale="1 1 1"/>
      </geometry>
    </collision>

    <inertial>
      <mass value="0.035"/>
      <inertia ixx="0.001" ixy="0.0" ixz="0.0" iyy="0.001" iyz="0.0" izz="0.001"/>
      <origin xyz="0 0 0" rpy="0 0 0"/>
    </inertial>
  </link>

  <!--##### back-top #####-->

  <link name="back_top">
    <visual>
      <origin xyz="0 0 0" rpy="0 0 0"/>
      <geometry>
        <mesh filename="/home/matthewthomasbeck/Projects/Robot_Dog/training/meshes/back/athena_back_top.dae" scale="1 1 1"/>
      </geometry>

      <material name="Grey">
          <color rgba="0.5 0.5 0.5 1"/>
      </material>
    </visual>

    <collision>
      <origin xyz="0 0 0" rpy="0 0 0"/>
      <geometry>
        <mesh filename="/home/matthewthomasbeck/Projects/Robot_Dog/training/meshes/back/athena_back_top.dae" scale="1 1 1"/>
      </geometry>
    </collision>

    <inertial>
      <mass value="0.017"/>
      <inertia ixx="0.001" ixy="0.0" ixz="0.0" iyy="0.001" iyz="0.0" izz="0.001"/>
      <origin xyz="0 0 0" rpy="0 0 0"/>
    </inertial>
  </link>


  <!--########## BACK JOINTS ##########-->

  <!--##### midsection-bottom/back-butt joint #####-->

  <joint name="midsection_bottom_back_butt" type="fixed">
    <parent link="midsection_bottom"/>
    <child link="back_butt"/>
    <origin xyz="-0.117 -0.394 -0.026" rpy="0 0 3.14"/>
  </joint>

  <!--##### back-butt/back-top joint #####-->

  <joint name="back_butt_back_top" type="fixed">
    <parent link="back_butt"/>
    <child link="back_top"/>
    <origin xyz="-0.0097 -1.118 -0.6045" rpy="0 0 3.14"/>
  </joint>


  <!--########## ELECTRONICS OBJECTS ##########-->

  <!--##### ai_module-mock #####-->

  <link name="ai_module_mock">
    <visual>
      <origin xyz="0 0 0" rpy="0 0 0"/>
      <geometry>
        <mesh filename="/home/matthewthomasbeck/Projects/Robot_Dog/training/meshes/electronics/ai_module_mock.dae" scale="1 1 1"/>
      </geometry>

      <material name="Blue">
        <color rgba="0 0 1 1"/>
      </material>
    </visual>

    <collision>
      <origin xyz="0 0 0" rpy="0 0 0"/>
      <geometry>
        <mesh filename="/home/matthewthomasbeck/Projects/Robot_Dog/training/meshes/electronics/ai_module_mock.dae" scale="1 1 1"/>
      </geometry>
    </collision>

    <inertial>
      <mass value="0.4"/>
      <inertia ixx="0.001" ixy="0.0" ixz="0.0" iyy="0.001" iyz="0.0" izz="0.001"/>
      <origin xyz="0 0 0" rpy="0 0 0"/>
    </inertial>
  </link>

  <!--##### battery ######-->

  <link name="battery">
    <visual>
      <origin xyz="0 0 0" rpy="0 0 0"/>
      <geometry>
        <mesh filename="/home/matthewthomasbeck/Projects/Robot_Dog/training/meshes/electronics/lipo_battery.dae" scale="1 1 1"/>
      </geometry>

      <material name="Yellow">
        <color rgba="1 1 0 1"/>
      </material>
    </visual>

    <collision>
      <origin xyz="0 0 0" rpy="0 0 0"/>
      <geometry>
        <mesh filename="/home/matthewthomasbeck/Projects/Robot_Dog/training/meshes/electronics/lipo_battery.dae" scale="1 1 1"/>
      </geometry>
    </collision>

    <inertial>
      <mass value="0.3"/>
      <inertia ixx="0.001" ixy="0.0" ixz="0.0" iyy="0.001" iyz="0.0" izz="0.001"/>
      <origin xyz="0 0 0" rpy="0 0 0"/>
    </inertial>
  </link>


  <!--########## ELECTRONICS JOINTS ##########-->

  <!--##### ai_module/midsection-connectorplate joint #####-->

  <joint name="ai_module_midsection_connectorplate" type="fixed">
    <parent link="midsection_connectorplate"/>
    <child link="ai_module_mock"/>
    <origin xyz="-0.00726 -0.074 0.0162" rpy="0 0 3.14"/>
  </joint>

  <!--##### battery/midsection-connectorplate joint #####-->

  <joint name="battery_midsection_batteryplate" type="fixed">
    <parent link="midsection_batteryplate"/>
    <child link="battery"/>
    <origin xyz="0.007 0.077 -0.0012" rpy="1.5708 0 0"/>
  </joint>


  <!--########## FRONT LEFT LEG OBJECTS ##########-->

  <!--##### front-left-pelvis-servo ######-->

  <link name="front_left_pelvis_servo">
    <visual>
      <origin xyz="0 0 0" rpy="0 0 0"/>
      <geometry>
        <mesh filename="/home/matthewthomasbeck/Projects/Robot_Dog/training/meshes/electronics/DS3218.dae" scale="1 1 1"/>
      </geometry>

      <material name="Red">
        <color rgba="1 0 0 1"/>
      </material>
    </visual>

    <collision>
      <origin xyz="0 0 0" rpy="0 0 0"/>
      <geometry>
        <mesh filename="/home/matthewthomasbeck/Projects/Robot_Dog/training/meshes/electronics/DS3218.dae" scale="1 1 1"/>
      </geometry>
    </collision>

    <inertial>
      <mass value="0.07"/>
      <inertia ixx="0.001" ixy="0.0" ixz="0.0" iyy="0.001" iyz="0.0" izz="0.001"/>
      <origin xyz="0 0 0" rpy="0 0 0"/>
    </inertial>
  </link>

  <!--##### front-left-pelvis-disc ######-->

  <link name="front_left_pelvis_disc">
    <visual>
      <origin xyz="0 0 0" rpy="0 0 0"/>
      <geometry>
        <mesh filename="/home/matthewthomasbeck/Projects/Robot_Dog/training/meshes/hardware/disc_servo_horn.dae" scale="1 1 1"/>
      </geometry>

      <material name="White">
        <color rgba="1 1 1 1"/>
      </material>
    </visual>

    <collision>
      <origin xyz="0 0 0" rpy="0 0 0"/>
      <geometry>
        <mesh filename="/home/matthewthomasbeck/Projects/Robot_Dog/training/meshes/hardware/disc_servo_horn.dae" scale="1 1 1"/>
      </geometry>
    </collision>

    <inertial>
      <mass value="0.002"/>
      <inertia ixx="0.001" ixy="0.0" ixz="0.0" iyy="0.001" iyz="0.0" izz="0.001"/>
      <origin xyz="0 0 0" rpy="0 0 0"/>
    </inertial>
  </link>

  <!--##### front-left-pelvis-pelvis #####-->

  <link name="front_left_pelvis_pelvis">
    <visual>
      <origin xyz="0 0 0" rpy="0 0 0"/>
      <geometry>
        <mesh filename="/home/matthewthomasbeck/Projects/Robot_Dog/training/meshes/pelvis/ares_pelvis_foreleft_hindright.dae" scale="1 1 1"/>
      </geometry>

      <material name="Grey">
        <color rgba="0.5 0.5 0.5 1"/>
      </material>
    </visual>

    <collision>
      <origin xyz="0 0 0" rpy="0 0 0"/>
      <geometry>
        <mesh filename="/home/matthewthomasbeck/Projects/Robot_Dog/training/meshes/pelvis/ares_pelvis_foreleft_hindright.dae" scale="1 1 1"/>
      </geometry>
    </collision>

    <inertial>
      <mass value="0.017"/>
      <inertia ixx="0.001" ixy="0.0" ixz="0.0" iyy="0.001" iyz="0.0" izz="0.001"/>
      <origin xyz="0 0 0" rpy="0 0 0"/>
    </inertial>
  </link>

  <!--##### front-left-shin-servo #####-->

  <link name="front_left_shin_servo">
    <visual>
      <origin xyz="0 0 0" rpy="0 0 0"/>
      <geometry>
        <mesh filename="/home/matthewthomasbeck/Projects/Robot_Dog/training/meshes/electronics/DS3218.dae" scale="1 1 1"/>
      </geometry>

      <material name="Red">
        <color rgba="1 0 0 1"/>
      </material>
    </visual>

    <collision>
      <origin xyz="0 0 0" rpy="0 0 0"/>
      <geometry>
        <mesh filename="/home/matthewthomasbeck/Projects/Robot_Dog/training/meshes/electronics/DS3218.dae" scale="1 1 1"/>
      </geometry>
    </collision>

    <inertial>
      <mass value="0.07"/>
      <inertia ixx="0.001" ixy="0.0" ixz="0.0" iyy="0.001" iyz="0.0" izz="0.001"/>
      <origin xyz="0 0 0" rpy="0 0 0"/>
    </inertial>
  </link>

  <!--##### front-left-shin-shin #####-->

  <link name="front_left_shin_shin">
    <visual>
      <origin xyz="0 0 0" rpy="0 0 0"/>
      <geometry>
        <mesh filename="/home/matthewthomasbeck/Projects/Robot_Dog/training/meshes/tibias/ares_tibias_left.dae" scale="1 1 1"/>
      </geometry>

      <material name="Grey">
        <color rgba="0.5 0.5 0.5 1"/>
      </material>
    </visual>

    <collision>
      <origin xyz="0 0 0" rpy="0 0 0"/>
      <geometry>
        <mesh filename="/home/matthewthomasbeck/Projects/Robot_Dog/training/meshes/tibias/ares_tibias_left.dae" scale="1 1 1"/>
      </geometry>
    </collision>

    <inertial>
      <mass value="0.009"/>
      <inertia ixx="0.001" ixy="0.0" ixz="0.0" iyy="0.001" iyz="0.0" izz="0.001"/>
      <origin xyz="0 0 0" rpy="0 0 0"/>
    </inertial>
  </link>

  <!--##### front-left-foot #####-->

  <link name="front_left_foot">
    <visual>
      <origin xyz="0 0 0" rpy="0 0 0"/>
      <geometry>
        <mesh filename="/home/matthewthomasbeck/Projects/Robot_Dog/training/meshes/feet/ares_feet_foot.dae" scale="1 1 1"/>
      </geometry>

      <material name="Grey">
        <color rgba="0.5 0.5 0.5 1"/>
      </material>
    </visual>

    <collision>
      <origin xyz="0 0 0" rpy="0 0 0"/>
      <geometry>
        <mesh filename="/home/matthewthomasbeck/Projects/Robot_Dog/training/meshes/feet/ares_feet_foot.dae" scale="1 1 1"/>
      </geometry>
    </collision>

    <inertial>
      <mass value="0.008"/>
      <inertia ixx="0.001" ixy="0.0" ixz="0.0" iyy="0.001" iyz="0.0" izz="0.001"/>
      <origin xyz="0 0 0" rpy="0 0 0"/>
    </inertial>
  </link>

  <!--##### front-left-femur-servo #####-->

  <link name="front_left_femur_servo">
    <visual>
      <origin xyz="0 0 0" rpy="0 0 0"/>
      <geometry>
        <mesh filename="/home/matthewthomasbeck/Projects/Robot_Dog/training/meshes/electronics/DS3218.dae" scale="1 1 1"/>
      </geometry>

      <material name="Red">
        <color rgba="1 0 0 1"/>
      </material>
    </visual>

    <collision>
      <origin xyz="0 0 0" rpy="0 0 0"/>
      <geometry>
        <mesh filename="/home/matthewthomasbeck/Projects/Robot_Dog/training/meshes/electronics/DS3218.dae" scale="1 1 1"/>
      </geometry>
    </collision>

    <inertial>
      <mass value="0.07"/>
      <inertia ixx="0.001" ixy="0.0" ixz="0.0" iyy="0.001" iyz="0.0" izz="0.001"/>
      <origin xyz="0 0 0" rpy="0 0 0"/>
    </inertial>
  </link>

  <!--##### front-left-femur-disc #####-->

  <link name="front_left_femur_disc">
    <visual>
      <origin xyz="0 0 0" rpy="0 0 0"/>
      <geometry>
        <mesh filename="/home/matthewthomasbeck/Projects/Robot_Dog/training/meshes/hardware/disc_servo_horn.dae" scale="1 1 1"/>
      </geometry>

      <material name="White">
          <color rgba="1 1 1 1"/>
      </material>
    </visual>

    <collision>
      <origin xyz="0 0 0" rpy="0 0 0"/>
      <geometry>
        <mesh filename="/home/matthewthomasbeck/Projects/Robot_Dog/training/meshes/hardware/disc_servo_horn.dae" scale="1 1 1"/>
      </geometry>
    </collision>

    <inertial>
      <mass value="0.002"/>
      <inertia ixx="0.001" ixy="0.0" ixz="0.0" iyy="0.001" iyz="0.0" izz="0.001"/>
      <origin xyz="0 0 0" rpy="0 0 0"/>
    </inertial>
  </link>

  <!--##### front-left-femur-femur #####-->

  <link name="front_left_femur_femur">
    <visual>
      <origin xyz="0 0 0" rpy="0 0 0"/>
      <geometry>
        <mesh filename="/home/matthewthomasbeck/Projects/Robot_Dog/training/meshes/femurs/ares_femurs_left.dae" scale="1 1 1"/>
      </geometry>

      <material name="Grey">
        <color rgba="0.5 0.5 0.5 1"/>
      </material>
    </visual>

    <collision>
      <origin xyz="0 0 0" rpy="0 0 0"/>
      <geometry>
        <mesh filename="/home/matthewthomasbeck/Projects/Robot_Dog/training/meshes/femurs/ares_femurs_left.dae" scale="1 1 1"/>
      </geometry>
    </collision>

    <inertial>
      <mass value="0.015"/>
      <inertia ixx="0.001" ixy="0.0" ixz="0.0" iyy="0.001" iyz="0.0" izz="0.001"/>
      <origin xyz="0 0 0" rpy="0 0 0"/>
    </inertial>
  </link>


  <!--########## TODO FRONT LEFT LEG JOINTS ##########-->

  <!--##### midsection-bottom/front-left-pelvis-servo joint #####-->

  <joint name="midsection_bottom_front_left_pelvis_servo" type="fixed">
    <parent link="midsection_bottom"/>
    <child link="front_left_pelvis_servo"/>
    <origin xyz="0.0005 0.05 0.0333" rpy="1.5708 3.14 0"/>
  </joint>

  <!--##### front-left-pelvis-servo/disc joint TODO (FL_hip) #####-->

  <joint name="FL_hip" type="revolute">
    <parent link="front_left_pelvis_servo"/>
    <child link="front_left_pelvis_disc"/>
    <origin xyz="0 -0.00995 0.04605" rpy="0 0 0"/>
    <axis xyz="0 0 1"/>
    <limit lower="-3.14159" upper="3.14159" effort="5.0" velocity="9.52"/>
    <dynamics friction="0.1" damping="0.005"/>
  </joint>

  <!--##### front-left-pelvis-disc/pelvis joint #####-->

  <joint name="front_left_pelvis_disc_pelvis" type="fixed">
    <parent link="front_left_pelvis_disc"/>
    <child link="front_left_pelvis_pelvis"/>
    <origin xyz="0 0.0425 0.00413" rpy="-1.5708 0 3.14"/>
  </joint>

  <!--##### front-left-pelvis-pelvis/front-left-shin-servo joint #####-->

  <joint name="front_left_pelvis_pelvis_front_left_shin_servo" type="fixed">
    <parent link="front_left_pelvis_pelvis"/>
    <child link="front_left_shin_servo"/>
    <origin xyz="-0.0175 -0.0271 0.0231" rpy="-1.5708 1.5708 -1.5708"/>
  </joint>

  <!--##### front-left-pelvis-pelvis/front-left-femur-servo joint #####-->

  <joint name="front_left_pelvis_pelvis_front_left_femur_servo" type="fixed">
    <parent link="front_left_pelvis_pelvis"/>
    <child link="front_left_femur_servo"/>
    <origin xyz="-0.0175 -0.0271 0.0431" rpy="0 -1.5708 -3.14"/>
  </joint>

  <!--##### front-left-femur-servo/disc joint TODO (FL_upper) #####-->

  <joint name="FL_upper" type="revolute">
    <parent link="front_left_femur_servo"/>
    <child link="front_left_femur_disc"/>
    <origin xyz="0 -0.01 0.047" rpy="0 0 0"/>
    <axis xyz="0 0 1"/>
    <limit lower="-3.14159" upper="3.14159" effort="5.0" velocity="9.52"/>
    <dynamics friction="0.1" damping="0.005"/>
  </joint>

  <!--##### front-left-femur-disc/femur joint #####-->

  <joint name="front_left_femur_disc_femur" type="fixed">
    <parent link="front_left_femur_disc"/>
    <child link="front_left_femur_femur"/>
    <origin xyz="0 0 0" rpy="0 -1.5708 3.14"/>
  </joint>

  <!--##### front-left-femur-femur/front-left-shin-shin joint TODO (FL_lower) #####-->

  <joint name="FL_lower" type="revolute">
    <parent link="front_left_femur_femur"/>
    <child link="front_left_shin_shin"/>
    <origin xyz="0.0076 0.07777 -0.07777" rpy="0 0 0"/>
    <axis xyz="1 0 0"/>
    <limit lower="-3.14159" upper="3.14159" effort="5.0" velocity="3.173"/>
    <dynamics friction="0.1" damping="0.005"/>
  </joint>

  <!--##### front-left-shin-shin/front-left-foot joint #####-->

  <joint name="front_left_shin_shin_front_left_foot" type="fixed">
    <parent link="front_left_shin_shin"/>
    <child link="front_left_foot"/>
    <origin xyz="-0.0367 -0.06 0.035" rpy="0 0 0"/>
  </joint>


  <!--########## FRONT RIGHT LEG OBJECTS ##########-->

  <!--##### front-right-pelvis-servo ######-->

  <link name="front_right_pelvis_servo">
    <visual>
      <origin xyz="0 0 0" rpy="0 0 0"/>
      <geometry>
        <mesh filename="/home/matthewthomasbeck/Projects/Robot_Dog/training/meshes/electronics/DS3218.dae" scale="1 1 1"/>
      </geometry>

      <material name="Red">
        <color rgba="1 0 0 1"/>
      </material>
    </visual>

    <collision>
      <origin xyz="0 0 0" rpy="0 0 0"/>
      <geometry>
        <mesh filename="/home/matthewthomasbeck/Projects/Robot_Dog/training/meshes/electronics/DS3218.dae" scale="1 1 1"/>
      </geometry>
    </collision>

    <inertial>
      <mass value="0.07"/>
      <inertia ixx="0.001" ixy="0.0" ixz="0.0" iyy="0.001" iyz="0.0" izz="0.001"/>
      <origin xyz="0 0 0" rpy="0 0 0"/>
    </inertial>
  </link>

  <!--##### front-right-pelvis-disc joint #####-->

  <link name="front_right_pelvis_disc">
    <visual>
      <origin xyz="0 0 0" rpy="0 0 0"/>
      <geometry>
        <mesh filename="/home/matthewthomasbeck/Projects/Robot_Dog/training/meshes/hardware/disc_servo_horn.dae" scale="1 1 1"/>
      </geometry>

      <material name="White">
        <color rgba="1 1 1 1"/>
      </material>
    </visual>

    <collision>
      <origin xyz="0 0 0" rpy="0 0 0"/>
      <geometry>
        <mesh filename="/home/matthewthomasbeck/Projects/Robot_Dog/training/meshes/hardware/disc_servo_horn.dae" scale="1 1 1"/>
      </geometry>
    </collision>

    <inertial>
      <mass value="0.002"/>
      <inertia ixx="0.001" ixy="0.0" ixz="0.0" iyy="0.001" iyz="0.0" izz="0.001"/>
      <origin xyz="0 0 0" rpy="0 0 0"/>
    </inertial>
  </link>

  <!--##### front-right-pelvis-pelvis ######-->

  <link name="front_right_pelvis_pelvis">
    <visual>
      <origin xyz="0 0 0" rpy="0 0 0"/>
      <geometry>
        <mesh filename="/home/matthewthomasbeck/Projects/Robot_Dog/training/meshes/pelvis/ares_pelvis_foreright_hindleft.dae" scale="1 1 1"/>
      </geometry>

      <material name="Grey">
        <color rgba="0.5 0.5 0.5 1"/>
      </material>
    </visual>

    <collision>
      <origin xyz="0 0 0" rpy="0 0 0"/>
      <geometry>
        <mesh filename="/home/matthewthomasbeck/Projects/Robot_Dog/training/meshes/pelvis/ares_pelvis_foreright_hindleft.dae" scale="1 1 1"/>
      </geometry>
    </collision>

    <inertial>
      <mass value="0.017"/>
      <inertia ixx="0.001" ixy="0.0" ixz="0.0" iyy="0.001" iyz="0.0" izz="0.001"/>
      <origin xyz="0 0 0" rpy="0 0 0"/>
    </inertial>
  </link>

  <!--##### front-right-shin-servo #####-->

  <link name="front_right_shin_servo">
    <visual>
      <origin xyz="0 0 0" rpy="0 0 0"/>
      <geometry>
        <mesh filename="/home/matthewthomasbeck/Projects/Robot_Dog/training/meshes/electronics/DS3218.dae" scale="1 1 1"/>
      </geometry>

      <material name="Red">
        <color rgba="1 0 0 1"/>
      </material>
    </visual>

    <collision>
      <origin xyz="0 0 0" rpy="0 0 0"/>
      <geometry>
        <mesh filename="/home/matthewthomasbeck/Projects/Robot_Dog/training/meshes/electronics/DS3218.dae" scale="1 1 1"/>
      </geometry>
    </collision>

    <inertial>
      <mass value="0.07"/>
      <inertia ixx="0.001" ixy="0.0" ixz="0.0" iyy="0.001" iyz="0.0" izz="0.001"/>
      <origin xyz="0 0 0" rpy="0 0 0"/>
    </inertial>
  </link>

  <!--##### front-right-shin-shin #####-->

  <link name="front_right_shin_shin">
    <visual>
      <origin xyz="0 0 0" rpy="0 0 0"/>
      <geometry>
        <mesh filename="/home/matthewthomasbeck/Projects/Robot_Dog/training/meshes/tibias/ares_tibias_right.dae" scale="1 1 1"/>
      </geometry>

      <material name="Grey">
        <color rgba="0.5 0.5 0.5 1"/>
      </material>
    </visual>

    <collision>
      <origin xyz="0 0 0" rpy="0 0 0"/>
      <geometry>
        <mesh filename="/home/matthewthomasbeck/Projects/Robot_Dog/training/meshes/tibias/ares_tibias_right.dae" scale="1 1 1"/>
      </geometry>
    </collision>

    <inertial>
      <mass value="0.009"/>
      <inertia ixx="0.001" ixy="0.0" ixz="0.0" iyy="0.001" iyz="0.0" izz="0.001"/>
      <origin xyz="0 0 0" rpy="0 0 0"/>
    </inertial>
  </link>

  <!--##### front-right-foot #####-->

  <link name="front_right_foot">
    <visual>
      <origin xyz="0 0 0" rpy="0 0 0"/>
      <geometry>
        <mesh filename="/home/matthewthomasbeck/Projects/Robot_Dog/training/meshes/feet/ares_feet_foot.dae" scale="1 1 1"/>
      </geometry>

      <material name="Grey">
        <color rgba="0.5 0.5 0.5 1"/>
      </material>
    </visual>

    <collision>
      <origin xyz="0 0 0" rpy="0 0 0"/>
      <geometry>
        <mesh filename="/home/matthewthomasbeck/Projects/Robot_Dog/training/meshes/feet/ares_feet_foot.dae" scale="1 1 1"/>
      </geometry>
    </collision>

    <inertial>
      <mass value="0.008"/>
      <inertia ixx="0.001" ixy="0.0" ixz="0.0" iyy="0.001" iyz="0.0" izz="0.001"/>
      <origin xyz="0 0 0" rpy="0 0 0"/>
    </inertial>
  </link>

  <!--##### front-right-femur-servo ######-->

  <link name="front_right_femur_servo">
    <visual>
      <origin xyz="0 0 0" rpy="0 0 0"/>
      <geometry>
        <mesh filename="/home/matthewthomasbeck/Projects/Robot_Dog/training/meshes/electronics/DS3218.dae" scale="1 1 1"/>
      </geometry>

      <material name="Red">
        <color rgba="1 0 0 1"/>
      </material>
    </visual>

    <collision>
      <origin xyz="0 0 0" rpy="0 0 0"/>
      <geometry>
        <mesh filename="/home/matthewthomasbeck/Projects/Robot_Dog/training/meshes/electronics/DS3218.dae" scale="1 1 1"/>
      </geometry>
    </collision>

    <inertial>
      <mass value="0.07"/>
      <inertia ixx="0.001" ixy="0.0" ixz="0.0" iyy="0.001" iyz="0.0" izz="0.001"/>
      <origin xyz="0 0 0" rpy="0 0 0"/>
    </inertial>
  </link>

  <!--##### front-right-femur-disc #####-->

  <link name="front_right_femur_disc">
    <visual>
      <origin xyz="0 0 0" rpy="0 0 0"/>
      <geometry>
        <mesh filename="/home/matthewthomasbeck/Projects/Robot_Dog/training/meshes/hardware/disc_servo_horn.dae" scale="1 1 1"/>
      </geometry>

      <material name="White">
          <color rgba="1 1 1 1"/>
      </material>
    </visual>

    <collision>
      <origin xyz="0 0 0" rpy="0 0 0"/>
      <geometry>
        <mesh filename="/home/matthewthomasbeck/Projects/Robot_Dog/training/meshes/hardware/disc_servo_horn.dae" scale="1 1 1"/>
      </geometry>
    </collision>

    <inertial>
      <mass value="0.002"/>
      <inertia ixx="0.001" ixy="0.0" ixz="0.0" iyy="0.001" iyz="0.0" izz="0.001"/>
      <origin xyz="0 0 0" rpy="0 0 0"/>
    </inertial>
  </link>

  <!--##### front-right-femur-femur #####-->

  <link name="front_right_femur_femur">
    <visual>
      <origin xyz="0 0 0" rpy="0 0 0"/>
      <geometry>
        <mesh filename="/home/matthewthomasbeck/Projects/Robot_Dog/training/meshes/femurs/ares_femurs_right.dae" scale="1 1 1"/>
      </geometry>

      <material name="Grey">
        <color rgba="0.5 0.5 0.5 1"/>
      </material>
    </visual>

    <collision>
      <origin xyz="0 0 0" rpy="0 0 0"/>
      <geometry>
        <mesh filename="/home/matthewthomasbeck/Projects/Robot_Dog/training/meshes/femurs/ares_femurs_right.dae" scale="1 1 1"/>
      </geometry>
    </collision>

    <inertial>
      <mass value="0.015"/>
      <inertia ixx="0.001" ixy="0.0" ixz="0.0" iyy="0.001" iyz="0.0" izz="0.001"/>
      <origin xyz="0 0 0" rpy="0 0 0"/>
    </inertial>
  </link>


  <!--########## TODO FRONT RIGHT LEG JOINTS ##########-->

  <!--##### midsection-bottom/front-right-pelvis-servo joint #####-->

  <joint name="midsection_bottom_front_right_pelvis_servo" type="fixed">
    <parent link="midsection_bottom"/>
    <child link="front_right_pelvis_servo"/>
    <origin xyz="-0.0975 0.05 0.0333" rpy="1.5708 3.14 0"/>
  </joint>

  <!--##### front-right-pelvis-servo/disc joint TODO (FR_hip) #####-->

  <joint name="FR_hip" type="revolute">
    <parent link="front_right_pelvis_servo"/>
    <child link="front_right_pelvis_disc"/>
    <origin xyz="0 -0.0106 0.04605" rpy="0 0 0"/>
    <axis xyz="0 0 1"/>
    <limit lower="-3.14159" upper="3.14159" effort="5.0" velocity="9.52"/>
    <dynamics friction="0.1" damping="0.005"/>
  </joint>

  <!--##### front-right-pelvis-disc/pelvis joint #####-->

  <joint name="front_right_pelvis_disc_pelvis" type="fixed">
    <parent link="front_right_pelvis_disc"/>
    <child link="front_right_pelvis_pelvis"/>
    <origin xyz="0 0.0425 0.00413" rpy="-1.5708 0 0"/>
  </joint>

  <!--##### front-right-pelvis-pelvis/front-right-shin-servo joint #####-->

  <joint name="front_right_pelvis_pelvis_front_right_shin_servo" type="fixed">
    <parent link="front_right_pelvis_pelvis"/>
    <child link="front_right_shin_servo"/>
    <origin xyz="-0.0175 -0.0271 -0.0231" rpy="1.5708 1.5708 1.5708"/>
  </joint>

  <!--##### front-right-pelvis-pelvis/front-right-femur-servo joint #####-->

  <joint name="front_right_pelvis_pelvis_front_right_femur_servo" type="fixed">
    <parent link="front_right_pelvis_pelvis"/>
    <child link="front_right_femur_servo"/>
    <origin xyz="-0.0175 -0.0271 -0.0431" rpy="0 -1.5708 -3.14"/>
  </joint>

  <!--##### front-right-femur-servo/disc joint TODO (FR_upper) #####-->

  <joint name="FR_upper" type="revolute">
    <parent link="front_right_femur_servo"/>
    <child link="front_right_femur_disc"/>
    <origin xyz="0 -0.01 0.047" rpy="0 0 0"/>
    <axis xyz="0 0 1"/>
    <limit lower="-3.14159" upper="3.14159" effort="5.0" velocity="9.52"/>
    <dynamics friction="0.1" damping="0.005"/>
  </joint>

  <!--##### front-right-femur-disc/femur joint #####-->

  <joint name="front_right_femur_disc_femur" type="fixed">
    <parent link="front_right_femur_disc"/>
    <child link="front_right_femur_femur"/>
    <origin xyz="0 0 0" rpy="0 1.5708 3.14"/>
  </joint>

  <!--##### front-right-femur-femur/front-right-shin-shin joint TODO (FR_lower) FLIPPED ROTATION DIRECTION #####-->

  <joint name="FR_lower" type="revolute">
    <parent link="front_right_femur_femur"/>
    <child link="front_right_shin_shin"/>
    <origin xyz="-0.0076 0.07777 -0.07777" rpy="0 0 0"/>
    <axis xyz="-1 0 0"/>
    <limit lower="-3.14159" upper="3.14159" effort="5.0" velocity="3.173"/>
    <dynamics friction="0.1" damping="0.005"/>
  </joint>

  <!--##### front-right-shin-shin/front-right-foot joint #####-->

    <joint name="front_right_shin_shin_front_right_foot" type="fixed">
    <parent link="front_right_shin_shin"/>
    <child link="front_right_foot"/>
    <origin xyz="-0.04258 -0.06 0.035" rpy="0 0 0"/>
  </joint>


  <!--########## BACK LEFT LEG OBJECTS ##########-->

  <!--##### back-left-pelvis-servo ######-->

  <link name="back_left_pelvis_servo">
    <visual>
      <origin xyz="0 0 0" rpy="0 0 0"/>
      <geometry>
        <mesh filename="/home/matthewthomasbeck/Projects/Robot_Dog/training/meshes/electronics/DS3218.dae" scale="1 1 1"/>
      </geometry>

      <material name="Red">
        <color rgba="1 0 0 1"/>
      </material>
    </visual>

    <collision>
      <origin xyz="0 0 0" rpy="0 0 0"/>
      <geometry>
        <mesh filename="/home/matthewthomasbeck/Projects/Robot_Dog/training/meshes/electronics/DS3218.dae" scale="1 1 1"/>
      </geometry>
    </collision>

    <inertial>
      <mass value="0.07"/>
      <inertia ixx="0.001" ixy="0.0" ixz="0.0" iyy="0.001" iyz="0.0" izz="0.001"/>
      <origin xyz="0 0 0" rpy="0 0 0"/>
    </inertial>
  </link>

  <!--##### back-left-pelvis-disc joint #####-->

  <link name="back_left_pelvis_disc">
    <visual>
      <origin xyz="0 0 0" rpy="0 0 0"/>
      <geometry>
        <mesh filename="/home/matthewthomasbeck/Projects/Robot_Dog/training/meshes/hardware/disc_servo_horn.dae" scale="1 1 1"/>
      </geometry>

      <material name="White">
        <color rgba="1 1 1 1"/>
      </material>
    </visual>

    <collision>
      <origin xyz="0 0 0" rpy="0 0 0"/>
      <geometry>
        <mesh filename="/home/matthewthomasbeck/Projects/Robot_Dog/training/meshes/hardware/disc_servo_horn.dae" scale="1 1 1"/>
      </geometry>
    </collision>

    <inertial>
      <mass value="0.002"/>
      <inertia ixx="0.001" ixy="0.0" ixz="0.0" iyy="0.001" iyz="0.0" izz="0.001"/>
      <origin xyz="0 0 0" rpy="0 0 0"/>
    </inertial>
  </link>

  <!--##### back-left-pelvis-pelvis ######-->

    <link name="back_left_pelvis_pelvis">
    <visual>
      <origin xyz="0 0 0" rpy="0 0 0"/>
      <geometry>
        <mesh filename="/home/matthewthomasbeck/Projects/Robot_Dog/training/meshes/pelvis/ares_pelvis_foreright_hindleft.dae" scale="1 1 1"/>
      </geometry>

      <material name="Grey">
        <color rgba="0.5 0.5 0.5 1"/>
      </material>
    </visual>

    <collision>
      <origin xyz="0 0 0" rpy="0 0 0"/>
      <geometry>
        <mesh filename="/home/matthewthomasbeck/Projects/Robot_Dog/training/meshes/pelvis/ares_pelvis_foreright_hindleft.dae" scale="1 1 1"/>
      </geometry>
    </collision>

    <inertial>
      <mass value="0.017"/>
      <inertia ixx="0.001" ixy="0.0" ixz="0.0" iyy="0.001" iyz="0.0" izz="0.001"/>
      <origin xyz="0 0 0" rpy="0 0 0"/>
    </inertial>
  </link>

  <!--##### back-left-shin-servo #####-->

  <link name="back_left_shin_servo">
    <visual>
      <origin xyz="0 0 0" rpy="0 0 0"/>
      <geometry>
        <mesh filename="/home/matthewthomasbeck/Projects/Robot_Dog/training/meshes/electronics/DS3218.dae" scale="1 1 1"/>
      </geometry>

      <material name="Red">
        <color rgba="1 0 0 1"/>
      </material>
    </visual>

    <collision>
      <origin xyz="0 0 0" rpy="0 0 0"/>
      <geometry>
        <mesh filename="/home/matthewthomasbeck/Projects/Robot_Dog/training/meshes/electronics/DS3218.dae" scale="1 1 1"/>
      </geometry>
    </collision>

    <inertial>
      <mass value="0.07"/>
      <inertia ixx="0.001" ixy="0.0" ixz="0.0" iyy="0.001" iyz="0.0" izz="0.001"/>
      <origin xyz="0 0 0" rpy="0 0 0"/>
    </inertial>
  </link>

  <!--##### back-left-shin-shin #####-->

  <link name="back_left_shin_shin">
    <visual>
      <origin xyz="0 0 0" rpy="0 0 0"/>
      <geometry>
        <mesh filename="/home/matthewthomasbeck/Projects/Robot_Dog/training/meshes/tibias/ares_tibias_left.dae" scale="1 1 1"/>
      </geometry>

      <material name="Grey">
        <color rgba="0.5 0.5 0.5 1"/>
      </material>
    </visual>

    <collision>
      <origin xyz="0 0 0" rpy="0 0 0"/>
      <geometry>
        <mesh filename="/home/matthewthomasbeck/Projects/Robot_Dog/training/meshes/tibias/ares_tibias_left.dae" scale="1 1 1"/>
      </geometry>
    </collision>

    <inertial>
      <mass value="0.009"/>
      <inertia ixx="0.001" ixy="0.0" ixz="0.0" iyy="0.001" iyz="0.0" izz="0.001"/>
      <origin xyz="0 0 0" rpy="0 0 0"/>
    </inertial>
  </link>

  <!--##### back-left-foot #####-->

  <link name="back_left_foot">
    <visual>
      <origin xyz="0 0 0" rpy="0 0 0"/>
      <geometry>
        <mesh filename="/home/matthewthomasbeck/Projects/Robot_Dog/training/meshes/feet/ares_feet_foot.dae" scale="1 1 1"/>
      </geometry>

      <material name="Grey">
        <color rgba="0.5 0.5 0.5 1"/>
      </material>
    </visual>

    <collision>
      <origin xyz="0 0 0" rpy="0 0 0"/>
      <geometry>
        <mesh filename="/home/matthewthomasbeck/Projects/Robot_Dog/training/meshes/feet/ares_feet_foot.dae" scale="1 1 1"/>
      </geometry>
    </collision>

    <inertial>
      <mass value="0.008"/>
      <inertia ixx="0.001" ixy="0.0" ixz="0.0" iyy="0.001" iyz="0.0" izz="0.001"/>
      <origin xyz="0 0 0" rpy="0 0 0"/>
    </inertial>
  </link>

  <!--##### back-left-femur-servo #####-->

  <link name="back_left_femur_servo">
    <visual>
      <origin xyz="0 0 0" rpy="0 0 0"/>
      <geometry>
        <mesh filename="/home/matthewthomasbeck/Projects/Robot_Dog/training/meshes/electronics/DS3218.dae" scale="1 1 1"/>
      </geometry>

      <material name="Red">
        <color rgba="1 0 0 1"/>
      </material>
    </visual>

    <collision>
      <origin xyz="0 0 0" rpy="0 0 0"/>
      <geometry>
        <mesh filename="/home/matthewthomasbeck/Projects/Robot_Dog/training/meshes/electronics/DS3218.dae" scale="1 1 1"/>
      </geometry>
    </collision>

    <inertial>
      <mass value="0.07"/>
      <inertia ixx="0.001" ixy="0.0" ixz="0.0" iyy="0.001" iyz="0.0" izz="0.001"/>
      <origin xyz="0 0 0" rpy="0 0 0"/>
    </inertial>
  </link>

  <!--##### back-left-femur-disc #####-->

  <link name="back_left_femur_disc">
    <visual>
      <origin xyz="0 0 0" rpy="0 0 0"/>
      <geometry>
        <mesh filename="/home/matthewthomasbeck/Projects/Robot_Dog/training/meshes/hardware/disc_servo_horn.dae" scale="1 1 1"/>
      </geometry>

      <material name="White">
          <color rgba="1 1 1 1"/>
      </material>
    </visual>

    <collision>
      <origin xyz="0 0 0" rpy="0 0 0"/>
      <geometry>
        <mesh filename="/home/matthewthomasbeck/Projects/Robot_Dog/training/meshes/hardware/disc_servo_horn.dae" scale="1 1 1"/>
      </geometry>
    </collision>

    <inertial>
      <mass value="0.002"/>
      <inertia ixx="0.001" ixy="0.0" ixz="0.0" iyy="0.001" iyz="0.0" izz="0.001"/>
      <origin xyz="0 0 0" rpy="0 0 0"/>
    </inertial>
  </link>

  <!--##### back-left-femur-femur #####-->

  <link name="back_left_femur_femur">
    <visual>
      <origin xyz="0 0 0" rpy="0 0 0"/>
      <geometry>
        <mesh filename="/home/matthewthomasbeck/Projects/Robot_Dog/training/meshes/femurs/ares_femurs_left.dae" scale="1 1 1"/>
      </geometry>

      <material name="Grey">
        <color rgba="0.5 0.5 0.5 1"/>
      </material>
    </visual>

    <collision>
      <origin xyz="0 0 0" rpy="0 0 0"/>
      <geometry>
        <mesh filename="/home/matthewthomasbeck/Projects/Robot_Dog/training/meshes/femurs/ares_femurs_left.dae" scale="1 1 1"/>
      </geometry>
    </collision>

    <inertial>
      <mass value="0.015"/>
      <inertia ixx="0.001" ixy="0.0" ixz="0.0" iyy="0.001" iyz="0.0" izz="0.001"/>
      <origin xyz="0 0 0" rpy="0 0 0"/>
    </inertial>
  </link>


  <!--########## TODO BACK LEFT LEG JOINTS ##########-->

  <!--##### midsection-bottom/back-left-pelvis-servo joint #####-->

  <joint name="midsection_bottom_back_left_pelvis_servo" type="fixed">
    <parent link="midsection_bottom"/>
    <child link="back_left_pelvis_servo"/>
    <origin xyz="0.0005 0.0785 0.0333" rpy="1.5708 3.14 3.14"/>
  </joint>

  <!--##### back-left-pelvis-servo/disc joint TODO (BL_hip) #####-->

  <joint name="BL_hip" type="revolute">
    <parent link="back_left_pelvis_servo"/>
    <child link="back_left_pelvis_disc"/>
    <origin xyz="0 -0.00995 0.04605" rpy="0 0 0"/>
    <axis xyz="0 0 1"/>
    <limit lower="-3.14159" upper="3.14159" effort="5.0" velocity="9.52"/>
    <dynamics friction="0.1" damping="0.005"/>
  </joint>

  <!--##### back-left-pelvis-disc/pelvis joint #####-->

  <joint name="back_left_pelvis_disc_pelvis" type="fixed">
    <parent link="back_left_pelvis_disc"/>
    <child link="back_left_pelvis_pelvis"/>
    <origin xyz="0 0.0425 0.00413" rpy="-1.5708 0 0"/>
  </joint>

  <!--##### back-left-pelvis-pelvis/back-left-shin-servo joint #####-->

  <joint name="back_left_pelvis_pelvis_back_left_shin_servo" type="fixed">
    <parent link="back_left_pelvis_pelvis"/>
    <child link="back_left_shin_servo"/>
    <origin xyz="-0.0175 -0.0271 -0.0231" rpy="1.5708 -1.5708 1.5708"/>
  </joint>

  <!--##### back-left-pelvis-pelvis/back-left-femur-servo joint #####-->

  <joint name="back_left_pelvis_pelvis_back_left_femur_servo" type="fixed">
    <parent link="back_left_pelvis_pelvis"/>
    <child link="back_left_femur_servo"/>
    <origin xyz="-0.0175 -0.0271 -0.0431" rpy="1.5708 1.5708 1.5708"/>
  </joint>

  <!--##### back-left-femur-servo/disc joint TODO (BL_upper) #####-->

  <joint name="BL_upper" type="revolute">
    <parent link="back_left_femur_servo"/>
    <child link="back_left_femur_disc"/>
    <origin xyz="0 -0.01 0.047" rpy="0 0 0"/>
    <axis xyz="0 0 1"/>
    <limit lower="-3.14159" upper="3.14159" effort="5.0" velocity="9.52"/>
    <dynamics friction="0.1" damping="0.005"/>
  </joint>

  <!--##### back-left-femur-disc/femur joint #####-->

  <joint name="back_left_femur_disc_femur" type="fixed">
    <parent link="back_left_femur_disc"/>
    <child link="back_left_femur_femur"/>
    <origin xyz="0 0 0" rpy="0 -1.5708 3.14"/>
  </joint>

  <!--##### back-left-femur-femur/back-left-shin-shin joint TODO (BL_lower) #####-->

  <joint name="BL_lower" type="revolute">
    <parent link="back_left_femur_femur"/>
    <child link="back_left_shin_shin"/>
    <origin xyz="0.0076 0.07777 -0.07777" rpy="0 0 0"/>
    <axis xyz="1 0 0"/>
    <limit lower="-3.14159" upper="3.14159" effort="5.0" velocity="3.173"/>
    <dynamics friction="0.1" damping="0.005"/>
  </joint>

  <!--##### back-left-shin-shin/back-left-foot joint #####-->

  <joint name="back_left_shin_shin_back_left_foot" type="fixed">
    <parent link="back_left_shin_shin"/>
    <child link="back_left_foot"/>
    <origin xyz="-0.0367 -0.06 0.035" rpy="0 0 0"/>
  </joint>


  <!--########## BACK RIGHT LEG OBJECTS ##########-->

  <!--##### back-right-pelvis-servo ######-->

  <link name="back_right_pelvis_servo">
    <visual>
      <origin xyz="0 0 0" rpy="0 0 0"/>
      <geometry>
        <mesh filename="/home/matthewthomasbeck/Projects/Robot_Dog/training/meshes/electronics/DS3218.dae" scale="1 1 1"/>
      </geometry>

      <material name="Red">
        <color rgba="1 0 0 1"/>
      </material>
    </visual>

    <collision>
      <origin xyz="0 0 0" rpy="0 0 0"/>
      <geometry>
        <mesh filename="/home/matthewthomasbeck/Projects/Robot_Dog/training/meshes/electronics/DS3218.dae" scale="1 1 1"/>
      </geometry>
    </collision>

    <inertial>
      <mass value="0.07"/>
      <inertia ixx="0.001" ixy="0.0" ixz="0.0" iyy="0.001" iyz="0.0" izz="0.001"/>
      <origin xyz="0 0 0" rpy="0 0 0"/>
    </inertial>
  </link>

  <!--##### back-right-pelvis-disc joint #####-->

  <link name="back_right_pelvis_disc">
    <visual>
      <origin xyz="0 0 0" rpy="0 0 0"/>
      <geometry>
        <mesh filename="/home/matthewthomasbeck/Projects/Robot_Dog/training/meshes/hardware/disc_servo_horn.dae" scale="1 1 1"/>
      </geometry>

      <material name="White">
        <color rgba="1 1 1 1"/>
      </material>
    </visual>

    <collision>
      <origin xyz="0 0 0" rpy="0 0 0"/>
      <geometry>
        <mesh filename="/home/matthewthomasbeck/Projects/Robot_Dog/training/meshes/hardware/disc_servo_horn.dae" scale="1 1 1"/>
      </geometry>
    </collision>

    <inertial>
      <mass value="0.002"/>
      <inertia ixx="0.001" ixy="0.0" ixz="0.0" iyy="0.001" iyz="0.0" izz="0.001"/>
      <origin xyz="0 0 0" rpy="0 0 0"/>
    </inertial>
  </link>

  <!--##### back-right-pelvis-pelvis #####-->

  <link name="back_right_pelvis_pelvis">
    <visual>
      <origin xyz="0 0 0" rpy="0 0 0"/>
      <geometry>
        <mesh filename="/home/matthewthomasbeck/Projects/Robot_Dog/training/meshes/pelvis/ares_pelvis_foreleft_hindright.dae" scale="1 1 1"/>
      </geometry>

      <material name="Grey">
        <color rgba="0.5 0.5 0.5 1"/>
      </material>
    </visual>

    <collision>
      <origin xyz="0 0 0" rpy="0 0 0"/>
      <geometry>
        <mesh filename="/home/matthewthomasbeck/Projects/Robot_Dog/training/meshes/pelvis/ares_pelvis_foreleft_hindright.dae" scale="1 1 1"/>
      </geometry>
    </collision>

    <inertial>
      <mass value="0.017"/>
      <inertia ixx="0.001" ixy="0.0" ixz="0.0" iyy="0.001" iyz="0.0" izz="0.001"/>
      <origin xyz="0 0 0" rpy="0 0 0"/>
    </inertial>
  </link>

  <!--##### back-right-shin-servo #####-->

  <link name="back_right_shin_servo">
    <visual>
      <origin xyz="0 0 0" rpy="0 0 0"/>
      <geometry>
        <mesh filename="/home/matthewthomasbeck/Projects/Robot_Dog/training/meshes/electronics/DS3218.dae" scale="1 1 1"/>
      </geometry>

      <material name="Red">
        <color rgba="1 0 0 1"/>
      </material>
    </visual>

    <collision>
      <origin xyz="0 0 0" rpy="0 0 0"/>
      <geometry>
        <mesh filename="/home/matthewthomasbeck/Projects/Robot_Dog/training/meshes/electronics/DS3218.dae" scale="1 1 1"/>
      </geometry>
    </collision>

    <inertial>
      <mass value="0.07"/>
      <inertia ixx="0.001" ixy="0.0" ixz="0.0" iyy="0.001" iyz="0.0" izz="0.001"/>
      <origin xyz="0 0 0" rpy="0 0 0"/>
    </inertial>
  </link>

  <!--##### back-right-shin-shin #####-->

  <link name="back_right_shin_shin">
    <visual>
      <origin xyz="0 0 0" rpy="0 0 0"/>
      <geometry>
        <mesh filename="/home/matthewthomasbeck/Projects/Robot_Dog/training/meshes/tibias/ares_tibias_right.dae" scale="1 1 1"/>
      </geometry>

      <material name="Grey">
        <color rgba="0.5 0.5 0.5 1"/>
      </material>
    </visual>

    <collision>
      <origin xyz="0 0 0" rpy="0 0 0"/>
      <geometry>
        <mesh filename="/home/matthewthomasbeck/Projects/Robot_Dog/training/meshes/tibias/ares_tibias_right.dae" scale="1 1 1"/>
      </geometry>
    </collision>

    <inertial>
      <mass value="0.009"/>
      <inertia ixx="0.001" ixy="0.0" ixz="0.0" iyy="0.001" iyz="0.0" izz="0.001"/>
      <origin xyz="0 0 0" rpy="0 0 0"/>
    </inertial>
  </link>

  <!--##### back-right-foot #####-->

  <link name="back_right_foot">
    <visual>
      <origin xyz="0 0 0" rpy="0 0 0"/>
      <geometry>
        <mesh filename="/home/matthewthomasbeck/Projects/Robot_Dog/training/meshes/feet/ares_feet_foot.dae" scale="1 1 1"/>
      </geometry>

      <material name="Grey">
        <color rgba="0.5 0.5 0.5 1"/>
      </material>
    </visual>

    <collision>
      <origin xyz="0 0 0" rpy="0 0 0"/>
      <geometry>
        <mesh filename="/home/matthewthomasbeck/Projects/Robot_Dog/training/meshes/feet/ares_feet_foot.dae" scale="1 1 1"/>
      </geometry>
    </collision>

    <inertial>
      <mass value="0.008"/>
      <inertia ixx="0.001" ixy="0.0" ixz="0.0" iyy="0.001" iyz="0.0" izz="0.001"/>
      <origin xyz="0 0 0" rpy="0 0 0"/>
    </inertial>
  </link>

  <!--##### back-right-femur-servo ######-->

  <link name="back_right_femur_servo">
    <visual>
      <origin xyz="0 0 0" rpy="0 0 0"/>
      <geometry>
        <mesh filename="/home/matthewthomasbeck/Projects/Robot_Dog/training/meshes/electronics/DS3218.dae" scale="1 1 1"/>
      </geometry>

      <material name="Red">
        <color rgba="1 0 0 1"/>
      </material>
    </visual>

    <collision>
      <origin xyz="0 0 0" rpy="0 0 0"/>
      <geometry>
        <mesh filename="/home/matthewthomasbeck/Projects/Robot_Dog/training/meshes/electronics/DS3218.dae" scale="1 1 1"/>
      </geometry>
    </collision>

    <inertial>
      <mass value="0.07"/>
      <inertia ixx="0.001" ixy="0.0" ixz="0.0" iyy="0.001" iyz="0.0" izz="0.001"/>
      <origin xyz="0 0 0" rpy="0 0 0"/>
    </inertial>
  </link>

  <!--##### back-right-femur-disc #####-->

  <link name="back_right_femur_disc">
    <visual>
      <origin xyz="0 0 0" rpy="0 0 0"/>
      <geometry>
        <mesh filename="/home/matthewthomasbeck/Projects/Robot_Dog/training/meshes/hardware/disc_servo_horn.dae" scale="1 1 1"/>
      </geometry>

      <material name="White">
          <color rgba="1 1 1 1"/>
      </material>
    </visual>

    <collision>
      <origin xyz="0 0 0" rpy="0 0 0"/>
      <geometry>
        <mesh filename="/home/matthewthomasbeck/Projects/Robot_Dog/training/meshes/hardware/disc_servo_horn.dae" scale="1 1 1"/>
      </geometry>
    </collision>

    <inertial>
      <mass value="0.002"/>
      <inertia ixx="0.001" ixy="0.0" ixz="0.0" iyy="0.001" iyz="0.0" izz="0.001"/>
      <origin xyz="0 0 0" rpy="0 0 0"/>
    </inertial>
  </link>

  <!--##### back-right-femur-femur #####-->

  <link name="back_right_femur_femur">
    <visual>
      <origin xyz="0 0 0" rpy="0 0 0"/>
      <geometry>
        <mesh filename="/home/matthewthomasbeck/Projects/Robot_Dog/training/meshes/femurs/ares_femurs_right.dae" scale="1 1 1"/>
      </geometry>

      <material name="Grey">
        <color rgba="0.5 0.5 0.5 1"/>
      </material>
    </visual>

    <collision>
      <origin xyz="0 0 0" rpy="0 0 0"/>
      <geometry>
        <mesh filename="/home/matthewthomasbeck/Projects/Robot_Dog/training/meshes/femurs/ares_femurs_right.dae" scale="1 1 1"/>
      </geometry>
    </collision>

    <inertial>
      <mass value="0.015"/>
      <inertia ixx="0.001" ixy="0.0" ixz="0.0" iyy="0.001" iyz="0.0" izz="0.001"/>
      <origin xyz="0 0 0" rpy="0 0 0"/>
    </inertial>
  </link>


  <!--########## TODO BACK RIGHT LEG JOINTS ##########-->

  <!--##### midsection-bottom/back-right-pelvis-servo joint #####-->

  <joint name="midsection_bottom_back_right_pelvis_servo" type="fixed">
    <parent link="midsection_bottom"/>
    <child link="back_right_pelvis_servo"/>
    <origin xyz="-0.0975 0.0785 0.0333" rpy="1.5708 3.14 3.14"/>
  </joint>

  <!--##### back-right-pelvis-servo/disc joint TODO (BR_hip) #####-->

  <joint name="BR_hip" type="revolute">
    <parent link="back_right_pelvis_servo"/>
    <child link="back_right_pelvis_disc"/>
    <origin xyz="0 -0.0106 0.04605" rpy="0 0 0"/>
    <axis xyz="0 0 1"/>
    <limit lower="-3.14159" upper="3.14159" effort="5.0" velocity="9.52"/>
    <dynamics friction="0.1" damping="0.005"/>
  </joint>

  <!--##### back-right-pelvis-disc/pelvis joint #####-->

  <joint name="back_right_pelvis_disc_pelvis" type="fixed">
    <parent link="back_right_pelvis_disc"/>
    <child link="back_right_pelvis_pelvis"/>
    <origin xyz="0 0.0425 0.00413" rpy="-1.5708 0 3.14"/>
  </joint>

    <!--##### back-right-pelvis-pelvis/back-right-shin-servo joint #####-->

  <joint name="back_right_pelvis_pelvis_back_right_shin_servo" type="fixed">
    <parent link="back_right_pelvis_pelvis"/>
    <child link="back_right_shin_servo"/>
    <origin xyz="-0.0175 -0.0271 0.0231" rpy="1.5708 -1.5708 1.5708"/>
  </joint>

  <!--##### back-right-pelvis-pelvis/back-right-femur-servo joint #####-->

  <joint name="back_right_pelvis_pelvis_back_right_femur_servo" type="fixed">
    <parent link="back_right_pelvis_pelvis"/>
    <child link="back_right_femur_servo"/>
    <origin xyz="-0.0175 -0.0271 0.0431" rpy="1.5708 1.5708 1.5708"/>
  </joint>

  <!--##### back-right-femur-servo/disc joint TODO (BR_upper) #####-->

  <joint name="BR_upper" type="revolute">
    <parent link="back_right_femur_servo"/>
    <child link="back_right_femur_disc"/>
    <origin xyz="0 -0.01 0.047" rpy="0 0 0"/>
    <axis xyz="0 0 1"/>
    <limit lower="-3.14159" upper="3.14159" effort="5.0" velocity="9.52"/>
    <dynamics friction="0.1" damping="0.005"/>
  </joint>

  <!--##### back-right-femur-disc/femur joint #####-->

  <joint name="back_right_femur_disc_femur" type="fixed">
    <parent link="back_right_femur_disc"/>
    <child link="back_right_femur_femur"/>
    <origin xyz="0 0 0" rpy="0 1.5708 3.14"/>
  </joint>

  <!--##### back-right-femur-femur/back-right-shin-shin joint TODO (BR_lower) FLIPPED ROTATION DIRECTION #####-->

  <joint name="BR_lower" type="revolute">
    <parent link="back_right_femur_femur"/>
    <child link="back_right_shin_shin"/>
    <origin xyz="-0.0076 0.07777 -0.07777" rpy="0 0 0"/>
    <axis xyz="-1 0 0"/>
    <limit lower="-3.14159" upper="3.14159" effort="5.0" velocity="3.173"/>
    <dynamics friction="0.1" damping="0.005"/>
  </joint>

  <!--##### back-right-shin-shin/back-right-foot joint #####-->

    <joint name="back_right_shin_shin_back_right_foot" type="fixed">
    <parent link="back_right_shin_shin"/>
    <child link="back_right_foot"/>
    <origin xyz="-0.04258 -0.06 0.035" rpy="0 0 0"/>
  </joint>
</robot>
